Workbook

Sheet Search Strings
A1: Inclusion Criterias | B1: Description | D1: Exclusion Criterias | E1: Description
A2: The study have a industrial focus, such as industrial automation, industrial control systems, industrial automation systems (IC1) | B2: Focus on industrial automation/ICS and closed‑loop/real‑time control contexts. | D2: The study is not available in full-text (EC1)
A3: The study describes industrial information‑exchange protocols (IC2) | D3: The study is not available in English (EC2)
A4: The study proposes a conceptual model, framework, or testbed for protocol evaluation (IC3) | D4: Unrelated domain - we are interested in automation systems (EC3)
A5: The study focuses on security or performance (IC4) | B5: Mentions security (encryption/authentication/IEC 62443/"secure communication"). Mentions performance/metrics (latency, jitter, overhead, determinism, stability). Although maybe including "performance" will limit the search results? Maybe only security and then extract any mentioned performance related metrics from the full text? | D5: Short papers with four pages or less (EC4)
A6: The study is published in a peer-reviewed publication (IC5) | D6: Secondary studies, such as other systematic literature reviews (SLRs), systematic mapping studies (SMSs), surveys etc. (EC5)
D7: Full proceedings (EC6)
D8: Exclude papers whose primary objective is not the experimental or theoretical evaluation of communication protocols, or the improvement of methods used for such evaluations. (EC7)
A14: Keywords | E14: Search Strings
A15: Focus | B15: Keyword(s) | E15: Database | F15: Search string | G15: #number matches
A16: Industrial Context (IC1) | B16: (IIoT OR "industrial iot" OR "industrial internet of things" OR "operational technology" OR "Industrial Control System" OR "Industrial Control Systems" OR "Industrial Automation System" OR "Industrial Automation Systems" OR "Industrial Automation and Control System" OR "Industrial Automation and Control Systems")
A17: Industrial information-exchange protocols (IC2) | B17: ("information‑exchange protocol" OR "information‑exchange protocols" OR "communication protocol" OR "communication protocols" OR "industrial protocol" OR "industrial protocols") | E17: IEEE | F17: (IIoT OR "industrial iot" OR "industrial internet of things" OR "operational technology" OR "Industrial Control System" OR "Industrial Control Systems" OR "Industrial Automation System" OR "Industrial Automation Systems" OR "Industrial Automation and Control System" OR "Industrial Automation and Control Systems") AND ("information‑exchange protocol" OR "information‑exchange protocols" OR "communication protocol" OR "communication protocols" OR "industrial protocol" OR "industrial protocols") AND (("performance" OR "security") NEAR/3 (evaluat* OR test* OR assess* OR compar* OR benchmark*)) AND ("conceptual model" OR "conceptual framework" OR "reference model" OR "domain model" OR "information model" OR metamodel OR ontology OR "reference architecture" OR "architecture description" OR testbed OR "test bench" OR testbench OR "experimental setup" OR "test harness" OR benchmarking OR benchmark* OR emulat* OR simulat* OR prototype OR "reference implementation" OR "software setup" OR "hardware setup") | G17: 107 | I17: https://ieeexplore-ieee-org.ep.bib.mdh.se/search/searchresult.jsp?action=search&matchBoolean=true&queryText=((IIoT%20OR%20%22industrial%20iot%22%20OR%20%22industrial%20internet%20of%20things%22%20OR%20%22operational%20technology%22%20OR%20%22Industrial%20Control%20System%22%20OR%20%22Industrial%20Control%20Systems%22%20OR%20%22Industrial%20Automation%20System%22%20OR%20%22Industrial%20Automation%20Systems%22%20OR%20%22Industrial%20Automation%20and%20Control%20System%22%20OR%20%22Industrial%20Automation%20and%20Control%20Systems%22)%20AND%20(%22information%E2%80%91exchange%20protocol%22%20OR%20%22information%E2%80%91exchange%20protocols%22%20OR%20%22communication%20protocol%22%20OR%20%22communication%20protocols%22%20OR%20%22industrial%20protocol%22%20OR%20%22industrial%20protocols%22)%20AND%20((%22performance%22%20OR%20%22security%22)%20NEAR%2F3%20(evaluat*%20OR%20test*%20OR%20assess*%20OR%20compar*%20OR%20benchmark*))%20AND%20(%22conceptual%20model%22%20OR%20%22conceptual%20framework%22%20OR%20%22reference%20model%22%20OR%20%22domain%20model%22%20OR%20%22information%20model%22%20OR%20metamodel%20OR%20ontology%20OR%20%22reference%20architecture%22%20OR%20%22architecture%20description%22%20OR%20testbed%20OR%20%22test%20bench%22%20OR%20testbench%20OR%20%22experimental%20setup%22%20OR%20%22test%20harness%22%20OR%20benchmarking%20OR%20benchmark*%20OR%20emulat*%20OR%20simulat*%20OR%20prototype%20OR%20%22reference%20implementation%22%20OR%20%22software%20setup%22%20OR%20%22hardware%20setup%22))&highlight=true&returnFacets=ALL&returnType=SEARCH&matchPubs=true&ranges=2016_2026_Year
A18: Conceptual model for protocol evaluation (IC3) | B18: ("conceptual model" OR "conceptual framework" OR "reference model" OR "domain model" OR "information model" OR metamodel OR ontology OR "reference architecture" OR "architecture description" OR testbed OR "test bench" OR testbench OR "experimental setup" OR "test harness" OR benchmarking OR benchmark* OR emulat* OR simulat* OR prototype OR "reference implementation" OR "software setup" OR "hardware setup") | E18: SCOPUS | F18: ( TITLE-ABS-KEY ( ( IIoT OR "industrial iot" OR "industrial internet of things" OR "operational technology" OR "Industrial Control System" OR "Industrial Control Systems" OR "Industrial Automation System" OR "Industrial Automation Systems" OR "Industrial Automation and Control System" OR "Industrial Automation and Control Systems" ) ) AND TITLE-ABS-KEY ( ( "information‑exchange protocol" OR "information‑exchange protocols" OR "communication protocol" OR "communication protocols" OR "industrial protocol" OR "industrial protocols" ) ) AND TITLE-ABS-KEY ( ( ( performance OR security ) W/3 ( evaluat* OR test* OR assess* OR compar* OR benchmark* ) ) ) AND TITLE-ABS-KEY ( ( "conceptual model" OR "conceptual framework" OR "reference model" OR "domain model" OR "information model" OR metamodel OR ontology OR "reference architecture" OR "architecture description" OR testbed OR "test bench" OR testbench OR "experimental setup" OR "test harness" OR benchmarking OR benchmark* OR emulat* OR simulat* OR prototype OR "reference implementation" OR "software setup" OR "hardware setup" ) ) ) AND PUBYEAR > 2015 AND PUBYEAR < 2026 AND ( LIMIT-TO ( DOCTYPE , "cp" ) OR LIMIT-TO ( DOCTYPE , "ar" ) ) | G18: 32 | I18: https://www-scopus-com.ep.bib.mdh.se/results/results.uri?sort=plf-f&src=s&sid=1349b548233cfe23a0b5a21aaad2b518&sot=a&sdt=a&cluster=scosubtype%2C%22cp%22%2Ct%2C%22ar%22%2Ct&sl=1146&s=%28+TITLE-ABS-KEY+%28+%28+IIoT+OR+%22industrial+iot%22+OR+%22industrial+internet+of+things%22+OR+%22operational+technology%22+OR+%22Industrial+Control+System%22+OR+%22Industrial+Control+Systems%22+OR+%22Industrial+Automation+System%22+OR+%22Industrial+Automation+Systems%22+OR+%22Industrial+Automation+and+Control+System%22+OR+%22Industrial+Automation+and+Control+Systems%22+%29+%29+AND+TITLE-ABS-KEY+%28+%28+%22information%26%238209%3Bexchange+protocol%22+OR+%22information%26%238209%3Bexchange+protocols%22+OR+%22communication+protocol%22+OR+%22communication+protocols%22+OR+%22industrial+protocol%22+OR+%22industrial+protocols%22+%29+%29+AND+TITLE-ABS-KEY+%28+%28+%28+performance+OR+security+%29+W%2F3+%28+evaluat*+OR+test*+OR+assess*+OR+compar*+OR+benchmark*+%29+%29+%29+AND+TITLE-ABS-KEY+%28+%28+%22conceptual+model%22+OR+%22conceptual+framework%22+OR+%22reference+model%22+OR+%22domain+model%22+OR+%22information+model%22+OR+metamodel+OR+ontology+OR+%22reference+architecture%22+OR+%22architecture+description%22+OR+testbed+OR+%22test+bench%22+OR+testbench+OR+%22experimental+setup%22+OR+%22test+harness%22+OR+benchmarking+OR+benchmark*+OR+emulat*+OR+simulat*+OR+prototype+OR+%22reference+implementation%22+OR+%22software+setup%22+OR+%22hardware+setup%22+%29+%29+%29+AND+PUBYEAR+%26gt%3B+2015+AND+PUBYEAR+%26lt%3B+2026&origin=searchadvanced&editSaveSearch=&txGid=766958fa8566bdc9fd88f0e955088426&sessionSearchId=1349b548233cfe23a0b5a21aaad2b518&limit=10
A19: The study focuses on security or performance (IC4) | B19: (("performance" OR "security") NEAR/3 (evaluat* OR test* OR assess* OR compar* OR benchmark*)) | E19: Web Of Science | F19: TS=((IIoT OR "industrial iot" OR "industrial internet of things" OR "operational technology" OR "industrial control system" OR "industrial control systems" OR "industrial automation system" OR "industrial automation systems" OR "industrial automation and control system" OR "industrial automation and control systems") AND ("information exchange protocol" OR "information exchange protocols" OR "communication protocol" OR "communication protocols" OR "industrial protocol" OR "industrial protocols") AND ((performance OR security) NEAR/3 (evaluat* OR test* OR assess* OR compar* OR benchmark*)) AND ("conceptual model" OR "conceptual framework" OR "reference model" OR "domain model" OR "information model" OR metamodel OR ontology OR "reference architecture" OR "architecture description" OR testbed OR "test bench" OR testbench OR "experimental setup" OR "test harness" OR benchmarking OR benchmark* OR emulat* OR simulat* OR prototype OR "reference implementation" OR "software setup" OR "hardware setup") ) | G19: 18 | I19: https://www.webofscience.com/wos/woscc/summary/20f4f276-9994-4d06-9ec7-00cb6cdb4fbd-019ec4b417/relevance/1
E20: ACM DL | F20: [[Abstract: iiot] OR [Abstract: "industrial iot"] OR [Abstract: "industrial internet of things"] OR [Abstract: "industrial control system"] OR [Abstract: "industrial control systems"] OR [Abstract: "industrial automation system"] OR [Abstract: "industrial automation systems"] OR [Abstract: "industrial automation and control system"] OR [Abstract: "industrial automation and control systems"]] AND [[Abstract: "information exchange protocol"] OR [Abstract: "information exchange protocols"] OR [Abstract: "communication protocol"] OR [Abstract: "communication protocols"] OR [Abstract: "industrial protocol"] OR [Abstract: "industrial protocols"]] AND [[Abstract: performance] OR [Abstract: security]] AND [[Abstract: evaluat*] OR [Abstract: test*] OR [Abstract: assess*] OR [Abstract: compar*] OR [Abstract: benchmark*]] AND [[Abstract: "conceptual model"] OR [Abstract: "conceptual framework"] OR [Abstract: "reference model"] OR [Abstract: "domain model"] OR [Abstract: "information model"] OR [Abstract: metamodel] OR [Abstract: ontology] OR [Abstract: "reference architecture"] OR [Abstract: "architecture description"] OR [Abstract: testbed] OR [Abstract: "test bench"] OR [Abstract: testbench] OR [Abstract: "experimental setup"] OR [Abstract: "test harness"] OR [Abstract: benchmarking] OR [Abstract: benchmark*] OR [Abstract: emulat*] OR [Abstract: simulat*] OR [Abstract: prototype] OR [Abstract: "reference implementation"] OR [Abstract: "software setup"] OR [Abstract: "hardware setup"]] | G20: 41 | I20: https://dl-acm-org.ep.bib.mdh.se/action/doSearch?fillQuickSearch=false&target=advanced&expand=dl&field1=Abstract&text1=%28+++%28IIoT+OR+%22industrial+iot%22+OR+%22industrial+internet+of+things%22++++OR+%22Industrial+Control+System%22+OR+%22Industrial+Control+Systems%22++++OR+%22Industrial+Automation+System%22+OR+%22Industrial+Automation+Systems%22++++OR+%22Industrial+Automation+and+Control+System%22+OR+%22Industrial+Automation+and+Control+Systems%22%29+++AND+++%28%22information+exchange+protocol%22+OR+%22information+exchange+protocols%22++++OR+%22communication+protocol%22+OR+%22communication+protocols%22++++OR+%22industrial+protocol%22+OR+%22industrial+protocols%22%29+++AND+++%28%28performance+OR+security%29+AND+%28evaluat*+OR+test*+OR+assess*+OR+compar*+OR+benchmark*%29%29+++AND+++%28%22conceptual+model%22+OR+%22conceptual+framework%22+OR+%22reference+model%22+OR+%22domain+model%22++++OR+%22information+model%22+OR+metamodel+OR+ontology+OR+%22reference+architecture%22++++OR+%22architecture+description%22+OR+testbed+OR+%22test+bench%22+OR+testbench++++OR+%22experimental+setup%22+OR+%22test+harness%22+OR+benchmarking+OR+benchmark*++++OR+emulat*+OR+simulat*+OR+prototype+OR+%22reference+implementation%22++++OR+%22software+setup%22+OR+%22hardware+setup%22%29+%29&startPage=0&pageSize=50

Sheet Results before duplicates
A1: Identifier | B1: Database | C1: Title | D1: Number of pages
A2: 0 | B2: IEEE | C2: =HYPERLINK(IEEE_NEW!$P2, IEEE_NEW!$A2) -> Towards a modular security testing framework for industrial automation and control systems: ISuTest | D2: =IEEE_NEW!$AC2 -> 5
A3: 1 | B3: IEEE | C3: =HYPERLINK(IEEE_NEW!$P3, IEEE_NEW!$A3) -> VTET: A Virtual Industrial Control System Testbed for Cyber Security Research | D3: =IEEE_NEW!$AC3 -> 7
A4: 2 | B4: IEEE | C4: =HYPERLINK(IEEE_NEW!$P4, IEEE_NEW!$A4) -> The SAir-IIoT Cyber Testbed as a Service: A Novel Cybertwins Architecture in IIoT-Based Smart Airports | D4: =IEEE_NEW!$AC4 -> 14
A5: 3 | B5: IEEE | C5: =HYPERLINK(IEEE_NEW!$P5, IEEE_NEW!$A5) -> Test Bed Development for a Security Engineered SCADA Laboratory | D5: =IEEE_NEW!$AC5 -> 5
A6: 4 | B6: IEEE | C6: =HYPERLINK(IEEE_NEW!$P6, IEEE_NEW!$A6) -> Industrial Internet of Things (IIoT): Testbed and Datasets for CyberSecurity and Digital Forensics | D6: =IEEE_NEW!$AC6 -> 10
A7: 5 | B7: IEEE | C7: =HYPERLINK(IEEE_NEW!$P7, IEEE_NEW!$A7) -> Improving Substation Network Security with DevSecOps and AIOps | D7: =IEEE_NEW!$AC7 -> 6
A8: 6 | B8: IEEE | C8: =HYPERLINK(IEEE_NEW!$P8, IEEE_NEW!$A8) -> Performance Evaluation of MQTT and CoAP Communication Protocols in IIoT for Electrical Substations Based on the IEC 61850 Standard | D8: =IEEE_NEW!$AC8 -> 6
A9: 7 | B9: IEEE | C9: =HYPERLINK(IEEE_NEW!$P9, IEEE_NEW!$A9) -> Behavior and Vulnerability Assessment of Drones-Enabled Industrial Internet of Things (IIoT) | D9: =IEEE_NEW!$AC9 -> 16
A10: 8 | B10: IEEE | C10: =HYPERLINK(IEEE_NEW!$P10, IEEE_NEW!$A10) -> Architecture of Modular System for Assessing Security of Telemetry Information Transmission System | D10: =IEEE_NEW!$AC10 -> 6
A11: 9 | B11: IEEE | C11: =HYPERLINK(IEEE_NEW!$P11, IEEE_NEW!$A11) -> Developing a Security Testbed for Industrial Internet of Things | D11: =IEEE_NEW!$AC11 -> 16
A12: 10 | B12: IEEE | C12: =HYPERLINK(IEEE_NEW!$P12, IEEE_NEW!$A12) -> SWaP: A Water Process Testbed for ICS Security Research | D12: =IEEE_NEW!$AC12 -> 4
A13: 11 | B13: IEEE | C13: =HYPERLINK(IEEE_NEW!$P13, IEEE_NEW!$A13) -> A Comparative Analysis of Application Layer Protocols Within an Industrial Internet of Things Monitoring System | D13: =IEEE_NEW!$AC13 -> 6
... A101: 99 | B101: IEEE | C101: =HYPERLINK(IEEE_NEW!$P101, IEEE_NEW!$A101) -> Energy-Efficient Wireless Sensor Networks Optimization using Deep Q-Networks for Smart Energy Applications | D101: =IEEE_NEW!$AC101 -> 5
A102: 100 | B102: ACM DL | C102: =HYPERLINK(ACM_NEW!$D2, ACM_NEW!$B2) -> ICSNet: A Hybrid-Interaction Honeynet for Industrial Control Systems | D102: =ACM_NEW!$H2 -> 12
A103: 101 | B103: ACM DL | C103: =HYPERLINK(ACM_NEW!$D3, ACM_NEW!$B3) -> RTPL: A Real-Time Communication Protocol for LoRa Network | D103: =ACM_NEW!$H3 -> 31
A104: 102 | B104: ACM DL | C104: =HYPERLINK(ACM_NEW!$D4, ACM_NEW!$B4) -> EmuFlex: A Flexible OT Testbed for Security Experiments with OPC UA | D104: =ACM_NEW!$H4 -> 9
A105: 103 | B105: ACM DL | C105: =HYPERLINK(ACM_NEW!$D5, ACM_NEW!$B5) -> A Comprehensive Survey on Interoperability for IIoT: Taxonomy, Standards, and Future Directions | D105: =ACM_NEW!$H5 -> 35
A106: 104 | B106: ACM DL | C106: =HYPERLINK(ACM_NEW!$D6, ACM_NEW!$B6) -> On Practical Realization of Evasion Attacks for Industrial Control Systems | D106: =ACM_NEW!$H6 -> 17
A107: 105 | B107: ACM DL | C107: =HYPERLINK(ACM_NEW!$D7, ACM_NEW!$B7) -> An Industrial Internet of Things (IIoT) platform for intelligent wind turbine gearbox fault detection with automatic annotation | D107: =ACM_NEW!$H7 -> 5
A108: 106 | B108: ACM DL | C108: =HYPERLINK(ACM_NEW!$D8, ACM_NEW!$B8) -> Examining the Suitability of Stream Ciphers for Modbus-TCP Encryption on Resource Constrained Devices | D108: =ACM_NEW!$H8 -> 7
A109: 107 | B109: ACM DL | C109: =HYPERLINK(ACM_NEW!$D9, ACM_NEW!$B9) -> HoneyICS: A High-interaction Physics-aware Honeynet for Industrial Control Systems | D109: =ACM_NEW!$H9 -> 10
A110: 108 | B110: ACM DL | C110: =HYPERLINK(ACM_NEW!$D10, ACM_NEW!$B10) -> The PRECINCT Ecosystem Platform for Critical Infrastructure Protection: Architecture, Deployment and Transferability | D110: =ACM_NEW!$H10 -> 8
A111: 109 | B111: ACM DL | C111: =HYPERLINK(ACM_NEW!$D11, ACM_NEW!$B11) -> Controller-in-the-Middle: Attacks on Software Defined Networks in Industrial Control Systems | D111: =ACM_NEW!$H11 -> 6
A112: 110 | B112: ACM DL | C112: =HYPERLINK(ACM_NEW!$D12, ACM_NEW!$B12) -> Identifying key attacks on an IEEE 9-Bus System by leveraging the MITRE ATT&amp;CK ICS Matrix | D112: =ACM_NEW!$H12 -> 8
A113: 111 | B113: ACM DL | C113: =HYPERLINK(ACM_NEW!$D13, ACM_NEW!$B13) -> SoK: A Taxonomy for Contrasting Industrial Control Systems Asset Discovery Tools | D113: =ACM_NEW!$H13 -> 12
... A140: 138 | B140: ACM DL | C140: =HYPERLINK(ACM_NEW!$D40, ACM_NEW!$B40) -> Sentinel: A Robust Intrusion Detection System for IoT Networks Using Kernel-Level System Information | D140: =ACM_NEW!$H40 -> 14
A141: 139 | B141: SCOPUS | C141: =HYPERLINK(SCOPUS_NEW!$N2, SCOPUS_NEW!$D2) -> Edge Computing-Enabled Predictive Maintenance System with Multi-Protocol RTU Integration for Industry 4.0 Applications | D141: =SCOPUS_NEW!$V2 -> 8
A142: 140 | B142: SCOPUS | C142: =HYPERLINK(SCOPUS_NEW!$N3, SCOPUS_NEW!$D3) -> Cyber4OT dataset: Network traces for cyber-security vulnerability evaluation in industrial control systems | D142: =SCOPUS_NEW!$V3 -> 0
A143: 141 | B143: SCOPUS | C143: =HYPERLINK(SCOPUS_NEW!$N4, SCOPUS_NEW!$D4) -> Exponential Backoff and Its Security Implications for Safety-Critical OT Protocols over TCP/IP Networks | D143: =SCOPUS_NEW!$V4 -> 0
A144: 142 | B144: SCOPUS | C144: =HYPERLINK(SCOPUS_NEW!$N5, SCOPUS_NEW!$D5) -> TSCH in Edge IoT: A Comprehensive Survey of Research Challenges | D144: =SCOPUS_NEW!$V5 -> 0
A145: 143 | B145: SCOPUS | C145: =HYPERLINK(SCOPUS_NEW!$N6, SCOPUS_NEW!$D6) -> Unleashing the Potential of Industrial IoT and Industry 5.0 | D145: =SCOPUS_NEW!$V6 -> 0
A146: 144 | B146: SCOPUS | C146: =HYPERLINK(SCOPUS_NEW!$N7, SCOPUS_NEW!$D7) -> Energy-Efficient Wireless Sensor Networks Optimization using Deep Q-Networks for Smart Energy Applications | D146: =SCOPUS_NEW!$V7 -> 4
A147: 145 | B147: SCOPUS | C147: =HYPERLINK(SCOPUS_NEW!$N8, SCOPUS_NEW!$D8) -> Methodology for Assessing Existing Vulnerabilities in Modbus Protocol | D147: =SCOPUS_NEW!$V8 -> 10
A148: 146 | B148: SCOPUS | C148: =HYPERLINK(SCOPUS_NEW!$N9, SCOPUS_NEW!$D9) -> IoTForge Pro: A Security Testbed for Generating Intrusion Dataset for Industrial IoT | D148: =SCOPUS_NEW!$V9 -> 7
A149: 147 | B149: SCOPUS | C149: =HYPERLINK(SCOPUS_NEW!$N10, SCOPUS_NEW!$D10) -> Simulation and modeling of a robust cybersecurity system for next-generation manufacturing execution | D149: =SCOPUS_NEW!$V10 -> 0
A150: 148 | B150: SCOPUS | C150: =HYPERLINK(SCOPUS_NEW!$N11, SCOPUS_NEW!$D11) -> Securing industrial control systems: Developing a SCADA/IoT test bench and evaluating lightweight cipher performance on hardware simulator | D150: =SCOPUS_NEW!$V11 -> 0
A151: 149 | B151: SCOPUS | C151: =HYPERLINK(SCOPUS_NEW!$N12, SCOPUS_NEW!$D12) -> OPC-UA in interoperability - a performance comparative testing | D151: =SCOPUS_NEW!$V12 -> 5
A152: 150 | B152: SCOPUS | C152: =HYPERLINK(SCOPUS_NEW!$N13, SCOPUS_NEW!$D13) -> A Comparative Analysis of Application Layer Protocols Within an Industrial Internet of Things Monitoring System | D152: =SCOPUS_NEW!$V13 -> 0
... A170: 168 | B170: SCOPUS | C170: =HYPERLINK(SCOPUS_NEW!$N31, SCOPUS_NEW!$D31) -> End-to-End Delay Evaluation of Industrial Automation Systems Based on EtherCAT | D170: =SCOPUS_NEW!$V31 -> 7
...

Sheet Results after duplicates
A1: Identifier | B1: Database | C1: Title | D1: Number of pages
A2: 0 | B2: IEEE | C2: =HYPERLINK(IEEE_NEW!$P2, IEEE_NEW!$A2) -> Towards a modular security testing framework for industrial automation and control systems: ISuTest | D2: =IEEE_NEW!$AC2 -> 5
A3: 1 | B3: IEEE | C3: =HYPERLINK(IEEE_NEW!$P3, IEEE_NEW!$A3) -> VTET: A Virtual Industrial Control System Testbed for Cyber Security Research | D3: =IEEE_NEW!$AC3 -> 7
A4: 2 | B4: IEEE | C4: =HYPERLINK(IEEE_NEW!$P4, IEEE_NEW!$A4) -> The SAir-IIoT Cyber Testbed as a Service: A Novel Cybertwins Architecture in IIoT-Based Smart Airports | D4: =IEEE_NEW!$AC4 -> 14
A5: 3 | B5: IEEE | C5: =HYPERLINK(IEEE_NEW!$P5, IEEE_NEW!$A5) -> Test Bed Development for a Security Engineered SCADA Laboratory | D5: =IEEE_NEW!$AC5 -> 5
A6: 4 | B6: IEEE | C6: =HYPERLINK(IEEE_NEW!$P6, IEEE_NEW!$A6) -> Industrial Internet of Things (IIoT): Testbed and Datasets for CyberSecurity and Digital Forensics | D6: =IEEE_NEW!$AC6 -> 10
A7: 5 | B7: IEEE | C7: =HYPERLINK(IEEE_NEW!$P7, IEEE_NEW!$A7) -> Improving Substation Network Security with DevSecOps and AIOps | D7: =IEEE_NEW!$AC7 -> 6
A8: 6 | B8: IEEE | C8: =HYPERLINK(IEEE_NEW!$P8, IEEE_NEW!$A8) -> Performance Evaluation of MQTT and CoAP Communication Protocols in IIoT for Electrical Substations Based on the IEC 61850 Standard | D8: =IEEE_NEW!$AC8 -> 6
A9: 7 | B9: IEEE | C9: =HYPERLINK(IEEE_NEW!$P9, IEEE_NEW!$A9) -> Behavior and Vulnerability Assessment of Drones-Enabled Industrial Internet of Things (IIoT) | D9: =IEEE_NEW!$AC9 -> 16
A10: 8 | B10: IEEE | C10: =HYPERLINK(IEEE_NEW!$P10, IEEE_NEW!$A10) -> Architecture of Modular System for Assessing Security of Telemetry Information Transmission System | D10: =IEEE_NEW!$AC10 -> 6
A11: 9 | B11: IEEE | C11: =HYPERLINK(IEEE_NEW!$P11, IEEE_NEW!$A11) -> Developing a Security Testbed for Industrial Internet of Things | D11: =IEEE_NEW!$AC11 -> 16
A12: 10 | B12: IEEE | C12: =HYPERLINK(IEEE_NEW!$P12, IEEE_NEW!$A12) -> SWaP: A Water Process Testbed for ICS Security Research | D12: =IEEE_NEW!$AC12 -> 4
A13: 11 | B13: IEEE | C13: =HYPERLINK(IEEE_NEW!$P13, IEEE_NEW!$A13) -> A Comparative Analysis of Application Layer Protocols Within an Industrial Internet of Things Monitoring System | D13: =IEEE_NEW!$AC13 -> 6
... A101: 99 | B101: IEEE | C101: =HYPERLINK(IEEE_NEW!$P101, IEEE_NEW!$A101) -> Energy-Efficient Wireless Sensor Networks Optimization using Deep Q-Networks for Smart Energy Applications | D101: =IEEE_NEW!$AC101 -> 5
A102: 100 | B102: ACM DL | C102: =HYPERLINK(ACM_NEW!$D2, ACM_NEW!$B2) -> ICSNet: A Hybrid-Interaction Honeynet for Industrial Control Systems | D102: =ACM_NEW!$H2 -> 12
A103: 101 | B103: ACM DL | C103: =HYPERLINK(ACM_NEW!$D3, ACM_NEW!$B3) -> RTPL: A Real-Time Communication Protocol for LoRa Network | D103: =ACM_NEW!$H3 -> 31
A104: 102 | B104: ACM DL | C104: =HYPERLINK(ACM_NEW!$D4, ACM_NEW!$B4) -> EmuFlex: A Flexible OT Testbed for Security Experiments with OPC UA | D104: =ACM_NEW!$H4 -> 9
A105: 103 | B105: ACM DL | C105: =HYPERLINK(ACM_NEW!$D5, ACM_NEW!$B5) -> A Comprehensive Survey on Interoperability for IIoT: Taxonomy, Standards, and Future Directions | D105: =ACM_NEW!$H5 -> 35
A106: 104 | B106: ACM DL | C106: =HYPERLINK(ACM_NEW!$D6, ACM_NEW!$B6) -> On Practical Realization of Evasion Attacks for Industrial Control Systems | D106: =ACM_NEW!$H6 -> 17
A107: 105 | B107: ACM DL | C107: =HYPERLINK(ACM_NEW!$D7, ACM_NEW!$B7) -> An Industrial Internet of Things (IIoT) platform for intelligent wind turbine gearbox fault detection with automatic annotation | D107: =ACM_NEW!$H7 -> 5
A108: 106 | B108: ACM DL | C108: =HYPERLINK(ACM_NEW!$D8, ACM_NEW!$B8) -> Examining the Suitability of Stream Ciphers for Modbus-TCP Encryption on Resource Constrained Devices | D108: =ACM_NEW!$H8 -> 7
A109: 107 | B109: ACM DL | C109: =HYPERLINK(ACM_NEW!$D9, ACM_NEW!$B9) -> HoneyICS: A High-interaction Physics-aware Honeynet for Industrial Control Systems | D109: =ACM_NEW!$H9 -> 10
A110: 108 | B110: ACM DL | C110: =HYPERLINK(ACM_NEW!$D10, ACM_NEW!$B10) -> The PRECINCT Ecosystem Platform for Critical Infrastructure Protection: Architecture, Deployment and Transferability | D110: =ACM_NEW!$H10 -> 8
A111: 109 | B111: ACM DL | C111: =HYPERLINK(ACM_NEW!$D11, ACM_NEW!$B11) -> Controller-in-the-Middle: Attacks on Software Defined Networks in Industrial Control Systems | D111: =ACM_NEW!$H11 -> 6
A112: 110 | B112: ACM DL | C112: =HYPERLINK(ACM_NEW!$D12, ACM_NEW!$B12) -> Identifying key attacks on an IEEE 9-Bus System by leveraging the MITRE ATT&amp;CK ICS Matrix | D112: =ACM_NEW!$H12 -> 8
A113: 111 | B113: ACM DL | C113: =HYPERLINK(ACM_NEW!$D13, ACM_NEW!$B13) -> SoK: A Taxonomy for Contrasting Industrial Control Systems Asset Discovery Tools | D113: =ACM_NEW!$H13 -> 12
... A140: 138 | B140: ACM DL | C140: =HYPERLINK(ACM_NEW!$D40, ACM_NEW!$B40) -> Sentinel: A Robust Intrusion Detection System for IoT Networks Using Kernel-Level System Information | D140: =ACM_NEW!$H40 -> 14
A141: 139 | B141: SCOPUS | C141: =HYPERLINK(SCOPUS_NEW!$N2, SCOPUS_NEW!$D2) -> Edge Computing-Enabled Predictive Maintenance System with Multi-Protocol RTU Integration for Industry 4.0 Applications | D141: =SCOPUS_NEW!$V2 -> 8
A142: 140 | B142: SCOPUS | C142: =HYPERLINK(SCOPUS_NEW!$N3, SCOPUS_NEW!$D3) -> Cyber4OT dataset: Network traces for cyber-security vulnerability evaluation in industrial control systems | D142: =SCOPUS_NEW!$V3 -> 0
A143: 141 | B143: SCOPUS | C143: =HYPERLINK(SCOPUS_NEW!$N4, SCOPUS_NEW!$D4) -> Exponential Backoff and Its Security Implications for Safety-Critical OT Protocols over TCP/IP Networks | D143: =SCOPUS_NEW!$V4 -> 0
A144: 142 | B144: SCOPUS | C144: =HYPERLINK(SCOPUS_NEW!$N5, SCOPUS_NEW!$D5) -> TSCH in Edge IoT: A Comprehensive Survey of Research Challenges | D144: =SCOPUS_NEW!$V5 -> 0
A145: 145 | B145: SCOPUS | C145: =HYPERLINK(SCOPUS_NEW!$N8, SCOPUS_NEW!$D8) -> Methodology for Assessing Existing Vulnerabilities in Modbus Protocol | D145: =SCOPUS_NEW!$V8 -> 10
A146: 147 | B146: SCOPUS | C146: =HYPERLINK(SCOPUS_NEW!$N10, SCOPUS_NEW!$D10) -> Simulation and modeling of a robust cybersecurity system for next-generation manufacturing execution | D146: =SCOPUS_NEW!$V10 -> 0
A147: 148 | B147: SCOPUS | C147: =HYPERLINK(SCOPUS_NEW!$N11, SCOPUS_NEW!$D11) -> Securing industrial control systems: Developing a SCADA/IoT test bench and evaluating lightweight cipher performance on hardware simulator | D147: =SCOPUS_NEW!$V11 -> 0
A148: 149 | B148: SCOPUS | C148: =HYPERLINK(SCOPUS_NEW!$N12, SCOPUS_NEW!$D12) -> OPC-UA in interoperability - a performance comparative testing | D148: =SCOPUS_NEW!$V12 -> 5
A149: 153 | B149: SCOPUS | C149: =HYPERLINK(SCOPUS_NEW!$N16, SCOPUS_NEW!$D16) -> SEAG: A novel dynamic security risk assessment method for industrial control systems with consideration of social engineering | D149: =SCOPUS_NEW!$V16 -> 0
A150: 154 | B150: SCOPUS | C150: =HYPERLINK(SCOPUS_NEW!$N17, SCOPUS_NEW!$D17) -> Secure Sensor Prototype Using Hardware Security Modules and Trusted Execution Environments in a Blockchain Application: Wine Logistic Use Case | D150: =SCOPUS_NEW!$V17 -> 0
A151: 162 | B151: SCOPUS | C151: =HYPERLINK(SCOPUS_NEW!$N25, SCOPUS_NEW!$D25) -> A performance analysis of internet of things networking protocols: Evaluating MQTT, CoAP, OPC UA | D151: =SCOPUS_NEW!$V25 -> 0
A152: 164 | B152: SCOPUS | C152: =HYPERLINK(SCOPUS_NEW!$N27, SCOPUS_NEW!$D27) -> Security Transformation Technology for Electricity Metering Communication Protocol; 电能计量用通信规约安全改造技术 | D152: =SCOPUS_NEW!$V27 -> 7
A153: 166 | B153: SCOPUS | C153: =HYPERLINK(SCOPUS_NEW!$N29, SCOPUS_NEW!$D29) -> SCADA Testbed Implementation, Attacks, and Security Solutions | D153: =SCOPUS_NEW!$V29 -> 19
...

Sheet Title_and_Abstract_Screening
A1: Identifier | B1: Database | C1: Title | D1: Number of pages | E1: Done (mark with 'O') | F1: EC1 | G1: EC2 | H1: EC3 | I1: EC4 | J1: EC5 | K1: EC6 | L1: EC7 | M1: Title Exclusion | N1: Decision | O1: Motivation
A2: 0 | B2: IEEE | C2: =HYPERLINK(IEEE_NEW!$P2, IEEE_NEW!$A2) -> Towards a modular security testing framework for industrial automation and control systems: ISuTest | D2: 5 | E2: O | I2: =IF(AND(D2>=1, D2<=4), "X", "") | N2: =IF(COUNTIF(F2:M2,"X")>0,"Exclude",IF(UPPER(TRIM(E2))="O","Include","")) -> Include | O2: Security testing frameworks/protocol robustness testing in IACS. method/framework for security testing, including protocol-facing robustness tests
A3: 1 | B3: IEEE | C3: =HYPERLINK(IEEE_NEW!$P3, IEEE_NEW!$A3) -> VTET: A Virtual Industrial Control System Testbed for Cyber Security Research | D3: 7 | E3: O | I3: =IF(AND(D3>=1, D3<=4), "X", "") | L3: X | N3: =IF(COUNTIF(F3:M3,"X")>0,"Exclude",IF(UPPER(TRIM(E3))="O","Include","")) -> Exclude | O3: ICS security testbed to run ICS attacks, not protocol evaluation.
A4: 2 | B4: IEEE | C4: =HYPERLINK(IEEE_NEW!$P4, IEEE_NEW!$A4) -> The SAir-IIoT Cyber Testbed as a Service: A Novel Cybertwins Architecture in IIoT-Based Smart Airports | D4: 14 | E4: O | I4: =IF(AND(D4>=1, D4<=4), "X", "") | L4: X | M4: X | N4: =IF(COUNTIF(F4:M4,"X")>0,"Exclude",IF(UPPER(TRIM(E4))="O","Include","")) -> Exclude | O4: Not a experimental/theoretical evaluation of communication protocols | Q4: Statistics (total) | R4: Count | S4: Percentage | U4: Statistics (title screening) | V4: Count | W4: Percentage | Y4: Statistics (abstract screening) | Z4: Count | AA4: Percentage
A5: 3 | B5: IEEE | C5: =HYPERLINK(IEEE_NEW!$P5, IEEE_NEW!$A5) -> Test Bed Development for a Security Engineered SCADA Laboratory | D5: 5 | E5: O | I5: =IF(AND(D5>=1, D5<=4), "X", "") | L5: X | N5: =IF(COUNTIF(F5:M5,"X")>0,"Exclude",IF(UPPER(TRIM(E5))="O","Include","")) -> Exclude | O5: no experimental/theoretical evaluation of communication protocols and no concrete protocol-evaluation method with reported protocol metrics/results | Q5: Total papers: | R5: =COUNTIF(A2:A162,"<>") -> 161 | U5: Total papers: | V5: =COUNTIF($A2:$A162,"<>") -> 161 | Y5: Total papers: | Z5: =$V7 -> 63
A6: 4 | B6: IEEE | C6: =HYPERLINK(IEEE_NEW!$P6, IEEE_NEW!$A6) -> Industrial Internet of Things (IIoT): Testbed and Datasets for CyberSecurity and Digital Forensics | D6: 10 | E6: O | I6: =IF(AND(D6>=1, D6<=4), "X", "") | L6: X | M6: X | N6: =IF(COUNTIF(F6:M6,"X")>0,"Exclude",IF(UPPER(TRIM(E6))="O","Include","")) -> Exclude | O6: testbed + datasets paper for cybersecurity/digital forensics, not an evaluation method for industrial information-exchange protocols. | Q6: Number excluded: | R6: =COUNTIF(N2:N162,"Exclude") -> 137 | S6: =(($R6/$R5)) -> 0.85093168 | U6: Number excluded: | V6: =COUNTIFS($N2:$N162,"Exclude",$M2:$M162,"X") -> 98 | W6: =((V6/V5)) -> 0.60869565 | Y6: Number excluded: | Z6: =COUNTIFS($N2:$N162,"Exclude",$M2:$M162,"<>X") -> 39 | AA6: =((Z6/Z5)) -> 0.61904762
A7: 5 | B7: IEEE | C7: =HYPERLINK(IEEE_NEW!$P7, IEEE_NEW!$A7) -> Improving Substation Network Security with DevSecOps and AIOps | D7: 6 | E7: O | I7: =IF(AND(D7>=1, D7<=4), "X", "") | L7: X | M7: X | N7: =IF(COUNTIF(F7:M7,"X")>0,"Exclude",IF(UPPER(TRIM(E7))="O","Include","")) -> Exclude | O7: doesn’t evaluate communication protocols or propose a protocol-evaluation method/metrics set | Q7: Number included: | R7: =COUNTIF(N2:N153,"Include") -> 21 | S7: =(($R7/$R5)) -> 0.13043478 | U7: Number included: | V7: =COUNTIFS($M2:$M162,"<>X",$E2:$E162,"O") -> 63 | W7: =((V7/V5)) -> 0.39130435 | Y7: Number included: | Z7: =COUNTIFS($N2:$N162,"Include", $M2:$M162,"<>X") -> 24 | AA7: =((Z7/Z5)) -> 0.38095238
A8: 6 | B8: IEEE | C8: =HYPERLINK(IEEE_NEW!$P8, IEEE_NEW!$A8) -> Performance Evaluation of MQTT and CoAP Communication Protocols in IIoT for Electrical Substations Based on the IEC 61850 Standard | D8: 6 | E8: O | I8: =IF(AND(D8>=1, D8<=4), "X", "") | N8: =IF(COUNTIF(F8:M8,"X")>0,"Exclude",IF(UPPER(TRIM(E8))="O","Include","")) -> Include | O8: Evaluates protocols MQTT vs CoAP using performance metrics, done in a industrial automation setting. Evaluates latency, jitter, bandwidth, throughput, packet loss using thir test bench | Q8: Type violation: | U8: Type violation: | Y8: Type violation:
A9: 7 | B9: IEEE | C9: =HYPERLINK(IEEE_NEW!$P9, IEEE_NEW!$A9) -> Behavior and Vulnerability Assessment of Drones-Enabled Industrial Internet of Things (IIoT) | D9: 16 | E9: O | I9: =IF(AND(D9>=1, D9<=4), "X", "") | L9: X | M9: X | N9: =IF(COUNTIF(F9:M9,"X")>0,"Exclude",IF(UPPER(TRIM(E9))="O","Include","")) -> Exclude | O9: Petri-net (HCAPN) model to assess drone behaviour, It does not experimentally/theoretically evaluate communication protocols. | Q9: EC1 | R9: =COUNTIF(F$2:F$162,"X") -> 3 | S9: =(($R9/$R$5)) -> 0.01863354 | U9: EC1 | V9: =COUNTIFS($F2:$F162,"X", $M2:$M162,"X") -> 1 | W9: =((V9/V$5)) -> 0.0062111801 | Y9: EC1 | Z9: =COUNTIFS($F2:$F162,"X", $M2:$M162,"<>X") -> 2 | AA9: =((Z9/Z$5)) -> 0.031746032
A10: 8 | B10: IEEE | C10: =HYPERLINK(IEEE_NEW!$P10, IEEE_NEW!$A10) -> Architecture of Modular System for Assessing Security of Telemetry Information Transmission System | D10: 6 | E10: O | H10: X | I10: =IF(AND(D10>=1, D10<=4), "X", "") | N10: =IF(COUNTIF(F10:M10,"X")>0,"Exclude",IF(UPPER(TRIM(E10))="O","Include","")) -> Exclude | O10: not an industrial automation / closed-loop control communication setting | Q10: EC2 | R10: =COUNTIF(G$2:G$162,"X") -> 1 | S10: =(($R10/$R$5)) -> 0.0062111801 | U10: EC2 | V10: =COUNTIFS($G2:$G162,"X", $M2:$M162,"X") -> 1 | W10: =((V10/V$5)) -> 0.0062111801 | Y10: EC2 | Z10: =COUNTIFS($G2:$G162,"X", $M2:$M162,"<>X") -> 0 | AA10: =((Z10/Z$5)) -> 0
A11: 9 | B11: IEEE | C11: =HYPERLINK(IEEE_NEW!$P11, IEEE_NEW!$A11) -> Developing a Security Testbed for Industrial Internet of Things | D11: 16 | E11: O | I11: =IF(AND(D11>=1, D11<=4), "X", "") | N11: =IF(COUNTIF(F11:M11,"X")>0,"Exclude",IF(UPPER(TRIM(E11))="O","Include","")) -> Include | O11: It proposes a reproducible end-to-end IIoT security, testbed (Brown-IIoTbed), which supports security testing and evaluation of different solutions. It also reports concrete protocol timing/jitter numbers as part of validating the testbed. "Brown-IIoTbed covers existing gaps in the development of IoT/IIoT system testbeds by supporting various new IIoT application protocols, legacy industrial protocols, the interoperability among them" | Q11: EC3 | R11: =COUNTIF(H$2:H$162,"X") -> 26 | S11: =(($R11/$R$5)) -> 0.16149068 | U11: EC3 | V11: =COUNTIFS($H2:$H162,"X", $M2:$M162,"X") -> 21 | W11: =((V11/V$5)) -> 0.13043478 | Y11: EC3 | Z11: =COUNTIFS($H2:$H162,"X", $M2:$M162,"<>X") -> 5 | AA11: =((Z11/Z$5)) -> 0.079365079
A12: 10 | B12: IEEE | C12: =HYPERLINK(IEEE_NEW!$P12, IEEE_NEW!$A12) -> SWaP: A Water Process Testbed for ICS Security Research | D12: 4 | E12: O | I12: =IF(AND(D12>=1, D12<=4), "X", "") -> X | N12: =IF(COUNTIF(F12:M12,"X")>0,"Exclude",IF(UPPER(TRIM(E12))="O","Include","")) -> Exclude | O12: Violates EC4, i.e., 4 pages or less | Q12: EC4 | R12: =COUNTIF(I$2:I$162,"X") -> 6 | S12: =(($R12/$R$5)) -> 0.037267081 | U12: EC4 | V12: =COUNTIFS($I2:$I162,"X", $M2:$M162,"X") -> 1 | W12: =((V12/V$5)) -> 0.0062111801 | Y12: EC4 | Z12: =COUNTIFS($I2:$I162,"X", $M2:$M162,"<>X") -> 5 | AA12: =((Z12/Z$5)) -> 0.079365079
A13: 11 | B13: IEEE | C13: =HYPERLINK(IEEE_NEW!$P13, IEEE_NEW!$A13) -> A Comparative Analysis of Application Layer Protocols Within an Industrial Internet of Things Monitoring System | D13: 6 | E13: O | I13: =IF(AND(D13>=1, D13<=4), "X", "") | N13: =IF(COUNTIF(F13:M13,"X")>0,"Exclude",IF(UPPER(TRIM(E13))="O","Include","")) -> Include | O13: Experimental performance evaluation of MQTT, CoAP, WebSockets, and HTTP. It utilize metrics such as average latency, jitter, throughput, and protocol efficiency. | Q13: EC5 | R13: =COUNTIF(J$2:J$162,"X") -> 9 | S13: =(($R13/$R$5)) -> 0.055900621 | U13: EC5 | V13: =COUNTIFS($J2:$J162,"X", $M2:$M162,"X") -> 5 | W13: =((V13/V$5)) -> 0.031055901 | Y13: EC5 | Z13: =COUNTIFS($J2:$J162,"X", $M2:$M162,"<>X") -> 4 | AA13: =((Z13/Z$5)) -> 0.063492063
A14: 12 | B14: IEEE | C14: =HYPERLINK(IEEE_NEW!$P14, IEEE_NEW!$A14) -> Application of Industrial Internet of Things with Edge Computing and Artificial Intelligence Models | D14: 4 | E14: O | I14: =IF(AND(D14>=1, D14<=4), "X", "") -> X | N14: =IF(COUNTIF(F14:M14,"X")>0,"Exclude",IF(UPPER(TRIM(E14))="O","Include","")) -> Exclude | O14: Violates EC4, i.e., 4 pages or less | Q14: EC6 | R14: =COUNTIF(K$2:K$162,"X") -> 0 | S14: =(($R14/$R$5)) -> 0 | U14: EC6 | V14: =COUNTIFS($K2:$K162,"X", $M2:$M162,"X") -> 0 | W14: =((V14/V$5)) -> 0 | Y14: EC6 | Z14: =COUNTIFS($K2:$K162,"X", $M2:$M162,"<>X") -> 0 | AA14: =((Z14/Z$5)) -> 0
A15: 13 | B15: IEEE | C15: =HYPERLINK(IEEE_NEW!$P15, IEEE_NEW!$A15) -> A Cyber-Security Methodology for a Cyber-Physical Industrial Control System Testbed | D15: 15 | E15: O | I15: =IF(AND(D15>=1, D15<=4), "X", "") | L15: X | N15: =IF(COUNTIF(F15:M15,"X")>0,"Exclude",IF(UPPER(TRIM(E15))="O","Include","")) -> Exclude | O15: Builds a hybrid ICS testbed that they use to inject false-data attacks via PROFINET, then cmpare online attack-detection algorithms. Does not experimantilly or theoretically evaluate communication protocols. | Q15: EC7 | R15: =COUNTIF(L$2:L$162,"X") -> 104 | S15: =(($R15/$R$5)) -> 0.64596273 | U15: EC7 | V15: =COUNTIFS($L2:$L162,"X", $M2:$M162,"X") -> 79 | W15: =((V15/V$5)) -> 0.49068323 | Y15: EC7 | Z15: =COUNTIFS($L2:$L162,"X", $M2:$M162,"<>X") -> 25 | AA15: =((Z15/Z$5)) -> 0.3968254
A16: 14 | B16: IEEE | C16: =HYPERLINK(IEEE_NEW!$P16, IEEE_NEW!$A16) -> SCADA-SST: a SCADA security testbed | D16: 6 | E16: O | I16: =IF(AND(D16>=1, D16<=4), "X", "") | L16: X | N16: =IF(COUNTIF(F16:M16,"X")>0,"Exclude",IF(UPPER(TRIM(E16))="O","Include","")) -> Exclude | O16: SCADA simulation environment for security testing. The evaluation example is DoS/DDoS on an RTU and tracking opened/dropped TCP connections, not evaluation of communication protocols or a protocol-assessment method with protocol metrics for closed-loop control. | Q16: Title Exclusion | R16: =COUNTIF(M$2:M$162,"X") -> 98 | S16: =(($R16/$R$5)) -> 0.60869565
A17: 15 | B17: IEEE | C17: =HYPERLINK(IEEE_NEW!$P17, IEEE_NEW!$A17) -> Design and Implementation of Full-Scale Industrial Control System Test Bed for Assessing Cyber-Security Defenses | D17: 6 | E17: O | I17: =IF(AND(D17>=1, D17<=4), "X", "") | L17: X | N17: =IF(COUNTIF(F17:M17,"X")>0,"Exclude",IF(UPPER(TRIM(E17))="O","Include","")) -> Exclude | O17: methodology + implementation of a realistic ICS test bed to validate cybersecurity defenses. Not an experimental/theoretical evaluation of communication protocols or a method for protocol evaluation.
A18: 16 | B18: IEEE | C18: =HYPERLINK(IEEE_NEW!$P18, IEEE_NEW!$A18) -> A dual-standard solution for industrial Wireless Sensor Network deployment: Experimental testbed and performance evaluation | D18: 9 | E18: O | I18: =IF(AND(D18>=1, D18<=4), "X", "") | N18: =IF(COUNTIF(F18:M18,"X")>0,"Exclude",IF(UPPER(TRIM(E18))="O","Include","")) -> Include | O18: performance evaluation of industrial wireless communication standards ISA100.11a and WirelessHART, including a dual-standard architecture. It uses a real testbed and reports protocol/network KPIs.
A19: 17 | B19: IEEE | C19: =HYPERLINK(IEEE_NEW!$P19, IEEE_NEW!$A19) -> Enhancing Industrial Communication Protocol Fuzz Testing Through Virtualization And Intelligent Guidance | D19: 5 | E19: O | I19: =IF(AND(D19>=1, D19<=4), "X", "") | N19: =IF(COUNTIF(F19:M19,"X")>0,"Exclude",IF(UPPER(TRIM(E19))="O","Include","")) -> Include | O19: Improving fuzz testing for industrial protocol security, then reports experimental evaluation (coverage, vulnerbility discovery, efficiency, resource use, etc).
A20: 18 | B20: IEEE | C20: =HYPERLINK(IEEE_NEW!$P20, IEEE_NEW!$A20) -> A virtual testbed for security management of industrial control systems | D20: 6 | E20: O | I20: =IF(AND(D20>=1, D20<=4), "X", "") | L20: X | N20: =IF(COUNTIF(F20:M20,"X")>0,"Exclude",IF(UPPER(TRIM(E20))="O","Include","")) -> Exclude | O20: building an ICS security testbed and simulating attacks, not “experimental or theoretical evaluation of communication protocols” or “improving methods used for such evaluations"
A21: 19 | B21: IEEE | C21: =HYPERLINK(IEEE_NEW!$P21, IEEE_NEW!$A21) -> Design, Analysis and Implementation of a Security Assessment/Enhancement Platform for Cyber-Physical Systems | D21: 11 | E21: O | I21: =IF(AND(D21>=1, D21<=4), "X", "") | L21: X | M21: X | N21: =IF(COUNTIF(F21:M21,"X")>0,"Exclude",IF(UPPER(TRIM(E21))="O","Include","")) -> Exclude | O21: Generic CPS platform; protocol evaluation not implied (EC7)
A22: 20 | B22: IEEE | C22: =HYPERLINK(IEEE_NEW!$P22, IEEE_NEW!$A22) -> Cyber security of industrial communication protocols | D22: 4 | E22: O | I22: =IF(AND(D22>=1, D22<=4), "X", "") -> X | N22: =IF(COUNTIF(F22:M22,"X")>0,"Exclude",IF(UPPER(TRIM(E22))="O","Include","")) -> Exclude | O22: Violates EC4, i.e., 4 pages or less
A23: 21 | B23: IEEE | C23: =HYPERLINK(IEEE_NEW!$P23, IEEE_NEW!$A23) -> A Comparative Study to Evaluate the Performance of Communication Protocols for Process Industry | D23: 8 | E23: O | I23: =IF(AND(D23>=1, D23<=4), "X", "") | N23: =IF(COUNTIF(F23:M23,"X")>0,"Exclude",IF(UPPER(TRIM(E23))="O","Include","")) -> Include | O23: test environment and performance evaluation of OPC UA vs MQTT with defined metrics and scenarios.
A24: 22 | B24: IEEE | C24: =HYPERLINK(IEEE_NEW!$P24, IEEE_NEW!$A24) -> Access Control Framework for Cross-Platform Interoperability in the Industrial Internet of Things | D24: 10 | E24: O | I24: =IF(AND(D24>=1, D24<=4), "X", "") | L24: X | M24: X | N24: =IF(COUNTIF(F24:M24,"X")>0,"Exclude",IF(UPPER(TRIM(E24))="O","Include","")) -> Exclude | O24: Contributes a access-control interoperability framework between IIoT platforms, not an evaluation of communication proto9cols
A25: 23 | B25: IEEE | C25: =HYPERLINK(IEEE_NEW!$P25, IEEE_NEW!$A25) -> The Cybersecurity Landscape in Industrial Control Systems | D25: 19 | E25: O | I25: =IF(AND(D25>=1, D25<=4), "X", "") | J25: X | M25: X | N25: =IF(COUNTIF(F25:M25,"X")>0,"Exclude",IF(UPPER(TRIM(E25))="O","Include","")) -> Exclude | O25: survey of the ICS security landscape
A26: 24 | B26: IEEE | C26: =HYPERLINK(IEEE_NEW!$P26, IEEE_NEW!$A26) -> IoTForge Pro: A Security Testbed for Generating Intrusion Dataset for Industrial IoT | D26: 8 | E26: O | I26: =IF(AND(D26>=1, D26<=4), "X", "") | L26: X | N26: =IF(COUNTIF(F26:M26,"X")>0,"Exclude",IF(UPPER(TRIM(E26))="O","Include","")) -> Exclude | O26: an IIoT security testbed that generates an intrusion dataset (ForgeIIOT) and then evaluates IDS/ML classifiers on that dataset. no experimental/theoretical evaluation of communication protocols and no concrete protocol-evaluation method with reported protocol metrics/results
A27: 25 | B27: IEEE | C27: =HYPERLINK(IEEE_NEW!$P27, IEEE_NEW!$A27) -> Ransomware in Resource-Constrained Industrial IoT Networks: There Actually is a Threat | D27: 8 | E27: O | I27: =IF(AND(D27>=1, D27<=4), "X", "") | L27: X | M27: X | N27: =IF(COUNTIF(F27:M27,"X")>0,"Exclude",IF(UPPER(TRIM(E27))="O","Include","")) -> Exclude | O27: ransomware in IIoT networks; nothing suggests protocol evaluation, benchmarking, or a reusable evaluation setup.
A28: 26 | B28: IEEE | C28: =HYPERLINK(IEEE_NEW!$P28, IEEE_NEW!$A28) -> Machine Learning-Based Network Vulnerability Analysis of Industrial Internet of Things | D28: 13 | E28: O | I28: =IF(AND(D28>=1, D28<=4), "X", "") | L28: X | M28: X | N28: =IF(COUNTIF(F28:M28,"X")>0,"Exclude",IF(UPPER(TRIM(E28))="O","Include","")) -> Exclude | O28: Security/vulnerability analysis using ML; typically not a protocol evaluation framework/testbed.
A29: 27 | B29: IEEE | C29: =HYPERLINK(IEEE_NEW!$P29, IEEE_NEW!$A29) -> CPS-IIoT-P2Attention: Explainable Privacy-Preserving With Scaled Dot-Product Attention in Cyber-Physical System-Industrial IoT Network | D29: 25 | E29: O | I29: =IF(AND(D29>=1, D29<=4), "X", "") | L29: X | M29: X | N29: =IF(COUNTIF(F29:M29,"X")>0,"Exclude",IF(UPPER(TRIM(E29))="O","Include","")) -> Exclude | O29: model development/IDS-style work, not protocol evaluation/testbed work.
A30: 28 | B30: IEEE | C30: =HYPERLINK(IEEE_NEW!$P30, IEEE_NEW!$A30) -> Network Simulation in a TCP-Enabled Industrial Internet of Things Environment-Reproducibility Issues for Performance Evaluation | D30: 9 | E30: O | I30: =IF(AND(D30>=1, D30<=4), "X", "") | L30: X | N30: =IF(COUNTIF(F30:M30,"X")>0,"Exclude",IF(UPPER(TRIM(E30))="O","Include","")) -> Exclude | O30: no experimental/theoretical evaluation of communication protocols and no concrete protocol-evaluation method with reported protocol metrics/results
A31: 29 | B31: IEEE | C31: =HYPERLINK(IEEE_NEW!$P31, IEEE_NEW!$A31) -> Securing IIoT Against DDoS attacks: A Stochastic Approach | D31: 6 | E31: O | I31: =IF(AND(D31>=1, D31<=4), "X", "") | L31: X | M31: X | N31: =IF(COUNTIF(F31:M31,"X")>0,"Exclude",IF(UPPER(TRIM(E31))="O","Include","")) -> Exclude | O31: DDoS mitigation via stochastic modelling; doesn’t signal protocol evaluation setup or benchmarking framework.
A32: 30 | B32: IEEE | C32: =HYPERLINK(IEEE_NEW!$P32, IEEE_NEW!$A32) -> Comparative Study on Smart Grid Security Testbeds Using MITRE ATT&CK Matrix | D32: 7 | E32: O | I32: =IF(AND(D32>=1, D32<=4), "X", "") | J32: X | L32: X | N32: =IF(COUNTIF(F32:M32,"X")>0,"Exclude",IF(UPPER(TRIM(E32))="O","Include","")) -> Exclude | O32: comparative study of smart-grid security testbeds (EPIC, KASTEL Lab, SGCR)
A33: 31 | B33: IEEE | C33: =HYPERLINK(IEEE_NEW!$P33, IEEE_NEW!$A33) -> A Survey on Industrial Control System Testbeds and Datasets for Security Research | D33: 47 | E33: O | I33: =IF(AND(D33>=1, D33<=4), "X", "") | J33: X | N33: =IF(COUNTIF(F33:M33,"X")>0,"Exclude",IF(UPPER(TRIM(E33))="O","Include","")) -> Exclude | O33: Violates EC5, a review paper
A34: 32 | B34: IEEE | C34: =HYPERLINK(IEEE_NEW!$P34, IEEE_NEW!$A34) -> Li-Fi in Industrial Environments: Performance Analysis Compared to Wi-Fi and Ethernet | D34: 6 | E34: O | I34: =IF(AND(D34>=1, D34<=4), "X", "") | L34: X | M34: X | N34: =IF(COUNTIF(F34:M34,"X")>0,"Exclude",IF(UPPER(TRIM(E34))="O","Include","")) -> Exclude | O34: Link-tech comparison, not industrial protocol evaluation (EC7)
A35: 33 | B35: IEEE | C35: =HYPERLINK(IEEE_NEW!$P35, IEEE_NEW!$A35) -> URLLC-Based Cooperative Industrial IoT Networks With Nonlinear Energy Harvesting | D35: 11 | E35: O | I35: =IF(AND(D35>=1, D35<=4), "X", "") | L35: X | M35: X | N35: =IF(COUNTIF(F35:M35,"X")>0,"Exclude",IF(UPPER(TRIM(E35))="O","Include","")) -> Exclude | O35: theoretical performance analysis of wireless relaying and energy harvesting, not evaluation or improvement of methods for assessing industrial communication protocols.
A36: 34 | B36: IEEE | C36: =HYPERLINK(IEEE_NEW!$P36, IEEE_NEW!$A36) -> Methodology for Analyzing the Performance of 5G-NR Networks During Initial Planning Without Deployment Using the NS-3 Network Simulator | D36: 5 | E36: O | H36: X | I36: =IF(AND(D36>=1, D36<=4), "X", "") | L36: X | M36: X | N36: =IF(COUNTIF(F36:M36,"X")>0,"Exclude",IF(UPPER(TRIM(E36))="O","Include","")) -> Exclude | O36: 5G planning/scheduling, not IACS closed-loop protocol evaluation and primary objective is scheduler/network performance, not evaluating secure industrial communication protocols or improving methods for that evaluation
A37: 35 | B37: IEEE | C37: =HYPERLINK(IEEE_NEW!$P37, IEEE_NEW!$A37) -> Cybersecurity of Digital Twins in Industrial IoT Environments | D37: 6 | E37: O | I37: =IF(AND(D37>=1, D37<=4), "X", "") | L37: X | M37: X | N37: =IF(COUNTIF(F37:M37,"X")>0,"Exclude",IF(UPPER(TRIM(E37))="O","Include","")) -> Exclude | O37: Digital twin security topic; no industrial comms protocol + no evaluation method/testbed framing.
A38: 36 | B38: IEEE | C38: =HYPERLINK(IEEE_NEW!$P38, IEEE_NEW!$A38) -> Security and Effectiveness Analysis of the Gateway Integrity Checking Protocol | D38: 9 | E38: O | I38: =IF(AND(D38>=1, D38<=4), "X", "") | N38: =IF(COUNTIF(F38:M38,"X")>0,"Exclude",IF(UPPER(TRIM(E38))="O","Include","")) -> Include | O38: theoretical and experimental evaluation of a protocol and its detection effectiveness
A39: 37 | B39: IEEE | C39: =HYPERLINK(IEEE_NEW!$P39, IEEE_NEW!$A39) -> Secure Onboarding of IIoT Devices using OPC UA | D39: 4 | E39: O | I39: =IF(AND(D39>=1, D39<=4), "X", "") -> X | N39: =IF(COUNTIF(F39:M39,"X")>0,"Exclude",IF(UPPER(TRIM(E39))="O","Include","")) -> Exclude | O39: Violates EC4, i.e., 4 pages or less
A40: 38 | B40: IEEE | C40: =HYPERLINK(IEEE_NEW!$P40, IEEE_NEW!$A40) -> On the Cost of Asset Discovery Techniques for Industrial Control Systems | D40: 6 | E40: O | I40: =IF(AND(D40>=1, D40<=4), "X", "") | L40: X | M40: X | N40: =IF(COUNTIF(F40:M40,"X")>0,"Exclude",IF(UPPER(TRIM(E40))="O","Include","")) -> Exclude | O40: Asset discovery, not protocol evaluation (EC7)
...

Sheet Fulltext_Screening
A1: Identifier | B1: Database | C1: Title | D1: Number of pages | E1: Done (mark with 'O') | F1: IC1 | G1: IC2 | H1: IC3 | I1: IC4 | J1: EC1 | K1: EC2 | L1: EC3 | M1: EC4 | N1: EC5 | O1: EC6 | P1: EC7 | Q1: Decision | R1: Motivation
A2: 0 | B2: IEEE | C2: =HYPERLINK(IEEE_NEW!$P2, IEEE_NEW!$A2) -> Towards a modular security testing framework for industrial automation and control systems: ISuTest | D2: 5 | E2: O | F2: X | G2: X | H2: X | I2: X | M2: =IF(AND(D2>=1, D2<=4), "X", "") | P2: X | Q2: =IF(OR(COUNTIF(J2:P2,"X")>0,COUNTIF(F2:I2,"X")<>4),"Exclude",IF(UPPER(TRIM(E2))="O","Include","")) -> Exclude | R2: Focusing on black-box vulnerability and communication robustness testing of IACS devices, not protocols
A3: 6 | B3: IEEE | C3: =HYPERLINK(IEEE_NEW!$P8, IEEE_NEW!$A8) -> Performance Evaluation of MQTT and CoAP Communication Protocols in IIoT for Electrical Substations Based on the IEC 61850 Standard | D3: 6 | E3: O | F3: X | G3: X | H3: X | I3: X | M3: =IF(AND(D3>=1, D3<=4), "X", "") | Q3: =IF(COUNTIF(J3:P3,"X")>0,"Exclude",IF(UPPER(TRIM(E3))="O","Include","")) -> Include | R3: Industrial power/IEC 61850 context + MQTT/CoAP + IEC 61850–IIoT test bench | Z3: Statistics (total) | AA3: Count | AB3: Percentage
A4: 9 | B4: IEEE | C4: =HYPERLINK(IEEE_NEW!$P11, IEEE_NEW!$A11) -> Developing a Security Testbed for Industrial Internet of Things | D4: 16 | E4: O | F4: X | G4: X | H4: X | I4: X | M4: =IF(AND(D4>=1, D4<=4), "X", "") | Q4: =IF(COUNTIF(J4:P4,"X")>0,"Exclude",IF(UPPER(TRIM(E4))="O","Include","")) -> Include | R4: Industrial/brownfield IIoT + security testbed aimed at assessment | Z4: Total papers: | AA4: =COUNTIF(A2:A25,"<>") -> 24
A5: 11 | B5: IEEE | C5: =HYPERLINK(IEEE_NEW!$P13, IEEE_NEW!$A13) -> A Comparative Analysis of Application Layer Protocols Within an Industrial Internet of Things Monitoring System | D5: 6 | E5: O | F5: X | G5: X | H5: X | I5: X | M5: =IF(AND(D5>=1, D5<=4), "X", "") | Q5: =IF(COUNTIF(J5:P5,"X")>0,"Exclude",IF(UPPER(TRIM(E5))="O","Include","")) -> Include | R5: Industrial monitoring context + protocol selection + experimental setup built for industrial scenario | Z5: Number excluded: | AA5: =COUNTIF(Q2:Q25,"Exclude") -> 11 | AB5: =(($AA5/$AA4)) -> 0.45833333
A6: 16 | B6: IEEE | C6: =HYPERLINK(IEEE_NEW!$P18, IEEE_NEW!$A18) -> A dual-standard solution for industrial Wireless Sensor Network deployment: Experimental testbed and performance evaluation | D6: 9 | E6: O | F6: X | G6: X | H6: X | I6: X | M6: =IF(AND(D6>=1, D6<=4), "X", "") | Q6: =IF(COUNTIF(J6:P6,"X")>0,"Exclude",IF(UPPER(TRIM(E6))="O","Include","")) -> Include | R6: Industrial WSN + named industrial protocols + real testbed + KPI performance evaluation | Z6: Number included: | AA6: =COUNTIF(Q2:Q25,"Include") -> 13 | AB6: =(($AA6/$AA4)) -> 0.54166667
A7: 17 | B7: IEEE | C7: =HYPERLINK(IEEE_NEW!$P19, IEEE_NEW!$A19) -> Enhancing Industrial Communication Protocol Fuzz Testing Through Virtualization And Intelligent Guidance | D7: 5 | E7: O | F7: X | G7: X | H7: X | I7: X | M7: =IF(AND(D7>=1, D7<=4), "X", "") | P7: X | Q7: =IF(COUNTIF(J7:P7,"X")>0,"Exclude",IF(UPPER(TRIM(E7))="O","Include","")) -> Exclude | R7: Focuses on enhancement of a fuzzing method (evaluation method improvement), targeting vulnerability finding, not an evaluation framework for comparing proötocols or their runtime performance/security trade-offs. | Z7: Type violation:
A8: 21 | B8: IEEE | C8: =HYPERLINK(IEEE_NEW!$P23, IEEE_NEW!$A23) -> A Comparative Study to Evaluate the Performance of Communication Protocols for Process Industry | D8: 8 | E8: O | F8: X | G8: X | H8: X | I8: X | M8: =IF(AND(D8>=1, D8<=4), "X", "") | Q8: =IF(COUNTIF(J8:P8,"X")>0,"Exclude",IF(UPPER(TRIM(E8))="O","Include","")) -> Include | R8: Industrial process setting + software-based test environment to evaluate protocol performance | Z8: EC1 | AA8: =COUNTIF(J$2:J$25,"X") -> 0 | AB8: =(($AA8/$AA$4)) -> 0
A9: 36 | B9: IEEE | C9: =HYPERLINK(IEEE_NEW!$P38, IEEE_NEW!$A38) -> Security and Effectiveness Analysis of the Gateway Integrity Checking Protocol | D9: 9 | E9: O | F9: X | I9: X | M9: =IF(AND(D9>=1, D9<=4), "X", "") | P9: X | Q9: =IF(COUNTIF(J9:P9,"X")>0,"Exclude",IF(UPPER(TRIM(E9))="O","Include","")) -> Exclude | R9: Focus is a gateway integrity protocol (GIP), not industrial information-exchange protocols evaluation/testbeds | Z9: EC2 | AA9: =COUNTIF(K$2:K$25,"X") -> 0 | AB9: =(($AA9/$AA$4)) -> 0
A10: 40 | B10: IEEE | C10: =HYPERLINK(IEEE_NEW!$P42, IEEE_NEW!$A42) -> Towards Performance Benchmarking of Cyclic OPC UA PubSub over TSN | D10: 8 | E10: O | F10: X | G10: X | H10: X | I10: X | M10: =IF(AND(D10>=1, D10<=4), "X", "") | Q10: =IF(COUNTIF(J10:P10,"X")>0,"Exclude",IF(UPPER(TRIM(E10))="O","Include","")) -> Include | R10: Industrial automation + OPC UA PubSub/TSN + experimental setup for performance benchmarking | Z10: EC3 | AA10: =COUNTIF(L$2:L$25,"X") -> 0 | AB10: =(($AA10/$AA$4)) -> 0
A11: 57 | B11: IEEE | C11: =HYPERLINK(IEEE_NEW!$P59, IEEE_NEW!$A59) -> End-to-End Delay Evaluation of Industrial Automation Systems Based on EtherCAT | D11: 8 | E11: O | F11: X | G11: X | H11: X | I11: X | M11: =IF(AND(D11>=1, D11<=4), "X", "") | Q11: =IF(COUNTIF(J11:P11,"X")>0,"Exclude",IF(UPPER(TRIM(E11))="O","Include","")) -> Include | R11: Industrial automation + EtherCAT + simulation-based evaluation setup for end-to-end delay | Z11: EC4 | AA11: =COUNTIF(M$2:M$25,"X") -> 0 | AB11: =(($AA11/$AA$4)) -> 0
A12: 78 | B12: IEEE | C12: =HYPERLINK(IEEE_NEW!$P80, IEEE_NEW!$A80) -> SenseFuzz: Black-box Fuzzing of ICS Protocols via Runtime Statistics Sensing | D12: 6 | E12: O | F12: X | G12: X | H12: X | I12: X | M12: =IF(AND(D12>=1, D12<=4), "X", "") | P12: X | Q12: =IF(COUNTIF(J12:P12,"X")>0,"Exclude",IF(UPPER(TRIM(E12))="O","Include","")) -> Exclude | R12: Focuses on enhancement of a fuzzing method (evaluation method improvement), method for improving protocol security testing. does not evaluate protocol behaviour, performance, or trade-offs in an industrial communication setup. | Z12: EC5 | AA12: =COUNTIF(N$2:N$25,"X") -> 0 | AB12: =(($AA12/$AA$4)) -> 0
A13: 82 | B13: IEEE | C13: =HYPERLINK(IEEE_NEW!$P84, IEEE_NEW!$A84) -> Experimenting With Digital Signatures Over a DNP3 Protocol in a Multitenant Cloud-Based SCADA Architecture | D13: 20 | E13: O | F13: X | G13: X | I13: X | M13: =IF(AND(D13>=1, D13<=4), "X", "") | P13: X | Q13: =IF(COUNTIF(J13:P13,"X")>0,"Exclude",IF(UPPER(TRIM(E13))="O","Include","")) -> Exclude | R13: Focus is adding security (signatures) and measuring overhead in one architecture; not a reusable evaluation framework/testbed for protocol comparison | Z13: EC6 | AA13: =COUNTIF(O$2:O$25,"X") -> 0 | AB13: =(($AA13/$AA$4)) -> 0
A14: 84 | B14: IEEE | C14: =HYPERLINK(IEEE_NEW!$P86, IEEE_NEW!$A86) -> Time Synchronization Extension for the IO-Link Industrial Communication Protocol | D14: 6 | E14: O | F14: X | G14: X | I14: X | M14: =IF(AND(D14>=1, D14<=4), "X", "") | P14: X | Q14: =IF(COUNTIF(J14:P14,"X")>0,"Exclude",IF(UPPER(TRIM(E14))="O","Include","")) -> Exclude | R14: Primary goal is protocol extension/design, not protocol evaluation framework/testbed | Z14: EC7 | AA14: =COUNTIF(P$2:P$25,"X") -> 11 | AB14: =(($AA14/$AA$4)) -> 0.45833333
A15: 86 | B15: IEEE | C15: =HYPERLINK(IEEE_NEW!$P88, IEEE_NEW!$A88) -> Priority-Aware Wireless Fieldbus Protocol for Mixed-Criticality Industrial Wireless Sensor Networks | D15: 14 | E15: O | F15: X | G15: X | H15: X | I15: X | M15: =IF(AND(D15>=1, D15<=4), "X", "") | P15: X | Q15: =IF(COUNTIF(J15:P15,"X")>0,"Exclude",IF(UPPER(TRIM(E15))="O","Include","")) -> Exclude | R15: Primary goal is designing a new protocol, not evaluating existing protocols / evaluation methods | Z15: IC1 | AA15: =COUNTIF(F$2:F$25,"<>X") -> 0 | AB15: =(($AA15/$AA$4)) -> 0
A16: 101 | B16: ACM DL | C16: =HYPERLINK(ACM_NEW!$D3, ACM_NEW!$B3) -> RTPL: A Real-Time Communication Protocol for LoRa Network | D16: 31 | E16: O | F16: X | G16: X | H16: X | I16: X | M16: =IF(AND(D16>=1, D16<=4), "X", "") | P16: X | Q16: =IF(COUNTIF(J16:P16,"X")>0,"Exclude",IF(UPPER(TRIM(E16))="O","Include","")) -> Exclude | R16: Primary goal is new protocol design for LoRa, not evaluation of existing industrial protocols / evaluation methods for them | Z16: IC2 | AA16: =COUNTIF(G$2:G$25,"<>X") -> 1 | AB16: =(($AA16/$AA$4)) -> 0.041666667
A17: 102 | B17: ACM DL | C17: =HYPERLINK(ACM_NEW!$D4, ACM_NEW!$B4) -> EmuFlex: A Flexible OT Testbed for Security Experiments with OPC UA | D17: 9 | E17: O | F17: X | G17: X | H17: X | I17: X | M17: =IF(AND(D17>=1, D17<=4), "X", "") | P17: X | Q17: =IF(COUNTIF(J17:P17,"X")>0,"Exclude",IF(UPPER(TRIM(E17))="O","Include","")) -> Exclude | R17: OT/IIoT + OPC UA + virtual testbed for security experiments, not protocol evaluation | Z17: IC3 | AA17: =COUNTIF(H$2:H$25,"<>X") -> 5 | AB17: =(($AA17/$AA$4)) -> 0.20833333
A18: 106 | B18: ACM DL | C18: =HYPERLINK(ACM_NEW!$D8, ACM_NEW!$B8) -> Examining the Suitability of Stream Ciphers for Modbus-TCP Encryption on Resource Constrained Devices | D18: 7 | E18: O | F18: X | G18: X | I18: X | M18: =IF(AND(D18>=1, D18<=4), "X", "") | P18: X | Q18: =IF(COUNTIF(J18:P18,"X")>0,"Exclude",IF(UPPER(TRIM(E18))="O","Include","")) -> Exclude | R18: Focus is crypto choice for Modbus-TCP encryption (component-level), not a reusable protocol evaluation framework/testbed | Z18: IC4 | AA18: =COUNTIF(I$2:I$25,"<>X") -> 1 | AB18: =(($AA18/$AA$4)) -> 0.041666667
A19: 123 | B19: ACM DL | C19: =HYPERLINK(ACM_NEW!$D25, ACM_NEW!$B25) -> Enabling Industry 4.0 Communication Protocol Interoperability: An OPC UA Case Study | D19: 9 | E19: O | F19: X | G19: X | M19: =IF(AND(D19>=1, D19<=4), "X", "") | P19: X | Q19: =IF(COUNTIF(J19:P19,"X")>0,"Exclude",IF(UPPER(TRIM(E19))="O","Include","")) -> Exclude | R19: Primary goal is integration/interoperability guidance, not protocol evaluation/benchmarking/testbed
A20: 141 | B20: SCOPUS | C20: =HYPERLINK(SCOPUS_NEW!$N4, SCOPUS_NEW!$D4) -> Exponential Backoff and Its Security Implications for Safety-Critical OT Protocols over TCP/IP Networks | D20: 0 | E20: O | F20: X | G20: X | H20: X | I20: X | M20: =IF(AND(D20>=1, D20<=4), "X", "") | Q20: =IF(COUNTIF(J20:P20,"X")>0,"Exclude",IF(UPPER(TRIM(E20))="O","Include","")) -> Include | R20: OT/IIoT + performance/security implications tied to TCP/IP behaviour affecting OT protocols + analysis aimed at evaluating robustness/performance impacts
A21: 149 | B21: SCOPUS | C21: =HYPERLINK(SCOPUS_NEW!$N12, SCOPUS_NEW!$D12) -> OPC-UA in interoperability - a performance comparative testing | D21: 5 | E21: O | F21: X | G21: X | H21: X | I21: X | M21: =IF(AND(D21>=1, D21<=4), "X", "") | Q21: =IF(COUNTIF(J21:P21,"X")>0,"Exclude",IF(UPPER(TRIM(E21))="O","Include","")) -> Include | R21: OPC UA + comparative performance testing approach for interoperability context
A22: 162 | B22: SCOPUS | C22: =HYPERLINK(SCOPUS_NEW!$N25, SCOPUS_NEW!$D25) -> A performance analysis of internet of things networking protocols: Evaluating MQTT, CoAP, OPC UA | D22: 0 | E22: O | F22: X | G22: X | H22: X | I22: X | M22: =IF(AND(D22>=1, D22<=4), "X", "") | Q22: =IF(COUNTIF(J22:P22,"X")>0,"Exclude",IF(UPPER(TRIM(E22))="O","Include","")) -> Include | R22: Covers industrial IoT use + named protocols + local testbed experiments (and broader experiments) on performance
